{
 "cells": [
  {
   "cell_type": "markdown",
   "metadata": {},
   "source": [
    "# VacationPy\n",
    "----\n",
    "\n",
    "#### Note\n",
    "* Keep an eye on your API usage. Use https://developers.google.com/maps/reporting/gmp-reporting as reference for how to monitor your usage and billing.\n",
    "\n",
    "* Instructions have been included for each segment. You do not have to follow them exactly, but they are included to help you think through the steps."
   ]
  },
  {
   "cell_type": "code",
   "execution_count": 6,
   "metadata": {},
   "outputs": [],
   "source": [
    "# Dependencies and Setup\n",
    "import matplotlib.pyplot as plt\n",
    "import pandas as pd\n",
    "import numpy as np\n",
    "import requests\n",
    "import gmaps\n",
    "import os\n",
    "\n",
    "# Import API key\n",
    "from config import apikey"
   ]
  },
  {
   "cell_type": "markdown",
   "metadata": {},
   "source": [
    "### Store Part I results into DataFrame\n",
    "* Load the csv exported in Part I to a DataFrame"
   ]
  },
  {
   "cell_type": "code",
   "execution_count": null,
   "metadata": {},
   "outputs": [
    {
     "name": "stderr",
     "output_type": "stream",
     "text": [
      "ERROR:root:Internal Python error in the inspect module.\n",
      "Below is the traceback from this internal error.\n",
      "\n"
     ]
    },
    {
     "name": "stdout",
     "output_type": "stream",
     "text": [
      "ERROR! Session/line number was not unique in database. History logging moved to new session 161\n",
      "Traceback (most recent call last):\n",
      "  File \"/Users/nicolebroussard/opt/anaconda3/envs/PythonData/lib/python3.6/site-packages/IPython/core/interactiveshell.py\", line 3343, in run_code\n",
      "    exec(code_obj, self.user_global_ns, self.user_ns)\n",
      "  File \"<ipython-input-7-f59d68021fd8>\", line 5, in <module>\n",
      "    city_data_df = pd.read_csv(csv_path)\n",
      "  File \"/Users/nicolebroussard/opt/anaconda3/envs/PythonData/lib/python3.6/site-packages/pandas/io/parsers.py\", line 676, in parser_f\n",
      "    return _read(filepath_or_buffer, kwds)\n",
      "  File \"/Users/nicolebroussard/opt/anaconda3/envs/PythonData/lib/python3.6/site-packages/pandas/io/parsers.py\", line 448, in _read\n",
      "    parser = TextFileReader(fp_or_buf, **kwds)\n",
      "  File \"/Users/nicolebroussard/opt/anaconda3/envs/PythonData/lib/python3.6/site-packages/pandas/io/parsers.py\", line 880, in __init__\n",
      "    self._make_engine(self.engine)\n",
      "  File \"/Users/nicolebroussard/opt/anaconda3/envs/PythonData/lib/python3.6/site-packages/pandas/io/parsers.py\", line 1114, in _make_engine\n",
      "    self._engine = CParserWrapper(self.f, **self.options)\n",
      "  File \"/Users/nicolebroussard/opt/anaconda3/envs/PythonData/lib/python3.6/site-packages/pandas/io/parsers.py\", line 1891, in __init__\n",
      "    self._reader = parsers.TextReader(src, **kwds)\n",
      "  File \"pandas/_libs/parsers.pyx\", line 374, in pandas._libs.parsers.TextReader.__cinit__\n",
      "  File \"pandas/_libs/parsers.pyx\", line 674, in pandas._libs.parsers.TextReader._setup_parser_source\n",
      "FileNotFoundError: [Errno 2] File ../output_data/cities.csv does not exist: '../output_data/cities.csv'\n",
      "\n",
      "During handling of the above exception, another exception occurred:\n",
      "\n",
      "Traceback (most recent call last):\n",
      "  File \"/Users/nicolebroussard/opt/anaconda3/envs/PythonData/lib/python3.6/site-packages/IPython/core/interactiveshell.py\", line 2044, in showtraceback\n",
      "    stb = value._render_traceback_()\n",
      "AttributeError: 'FileNotFoundError' object has no attribute '_render_traceback_'\n",
      "\n",
      "During handling of the above exception, another exception occurred:\n",
      "\n",
      "Traceback (most recent call last):\n",
      "  File \"/Users/nicolebroussard/opt/anaconda3/envs/PythonData/lib/python3.6/site-packages/IPython/core/ultratb.py\", line 1169, in get_records\n",
      "    return _fixed_getinnerframes(etb, number_of_lines_of_context, tb_offset)\n",
      "  File \"/Users/nicolebroussard/opt/anaconda3/envs/PythonData/lib/python3.6/site-packages/IPython/core/ultratb.py\", line 316, in wrapped\n",
      "    return f(*args, **kwargs)\n",
      "  File \"/Users/nicolebroussard/opt/anaconda3/envs/PythonData/lib/python3.6/site-packages/IPython/core/ultratb.py\", line 350, in _fixed_getinnerframes\n",
      "    records = fix_frame_records_filenames(inspect.getinnerframes(etb, context))\n",
      "  File \"/Users/nicolebroussard/opt/anaconda3/envs/PythonData/lib/python3.6/inspect.py\", line 1490, in getinnerframes\n",
      "    frameinfo = (tb.tb_frame,) + getframeinfo(tb, context)\n",
      "  File \"/Users/nicolebroussard/opt/anaconda3/envs/PythonData/lib/python3.6/inspect.py\", line 1448, in getframeinfo\n",
      "    filename = getsourcefile(frame) or getfile(frame)\n",
      "  File \"/Users/nicolebroussard/opt/anaconda3/envs/PythonData/lib/python3.6/inspect.py\", line 696, in getsourcefile\n",
      "    if getattr(getmodule(object, filename), '__loader__', None) is not None:\n",
      "  File \"/Users/nicolebroussard/opt/anaconda3/envs/PythonData/lib/python3.6/inspect.py\", line 725, in getmodule\n",
      "    file = getabsfile(object, _filename)\n",
      "  File \"/Users/nicolebroussard/opt/anaconda3/envs/PythonData/lib/python3.6/inspect.py\", line 709, in getabsfile\n",
      "    return os.path.normcase(os.path.abspath(_filename))\n",
      "  File \"/Users/nicolebroussard/opt/anaconda3/envs/PythonData/lib/python3.6/posixpath.py\", line 383, in abspath\n",
      "    cwd = os.getcwd()\n",
      "PermissionError: [Errno 1] Operation not permitted\n"
     ]
    },
    {
     "name": "stderr",
     "output_type": "stream",
     "text": [
      "ERROR:root:Internal Python error in the inspect module.\n",
      "Below is the traceback from this internal error.\n",
      "\n"
     ]
    },
    {
     "name": "stdout",
     "output_type": "stream",
     "text": [
      "Traceback (most recent call last):\n",
      "  File \"/Users/nicolebroussard/opt/anaconda3/envs/PythonData/lib/python3.6/site-packages/IPython/core/interactiveshell.py\", line 3343, in run_code\n",
      "    exec(code_obj, self.user_global_ns, self.user_ns)\n",
      "  File \"<ipython-input-7-f59d68021fd8>\", line 5, in <module>\n",
      "    city_data_df = pd.read_csv(csv_path)\n",
      "  File \"/Users/nicolebroussard/opt/anaconda3/envs/PythonData/lib/python3.6/site-packages/pandas/io/parsers.py\", line 676, in parser_f\n",
      "    return _read(filepath_or_buffer, kwds)\n",
      "  File \"/Users/nicolebroussard/opt/anaconda3/envs/PythonData/lib/python3.6/site-packages/pandas/io/parsers.py\", line 448, in _read\n",
      "    parser = TextFileReader(fp_or_buf, **kwds)\n",
      "  File \"/Users/nicolebroussard/opt/anaconda3/envs/PythonData/lib/python3.6/site-packages/pandas/io/parsers.py\", line 880, in __init__\n",
      "    self._make_engine(self.engine)\n",
      "  File \"/Users/nicolebroussard/opt/anaconda3/envs/PythonData/lib/python3.6/site-packages/pandas/io/parsers.py\", line 1114, in _make_engine\n",
      "    self._engine = CParserWrapper(self.f, **self.options)\n",
      "  File \"/Users/nicolebroussard/opt/anaconda3/envs/PythonData/lib/python3.6/site-packages/pandas/io/parsers.py\", line 1891, in __init__\n",
      "    self._reader = parsers.TextReader(src, **kwds)\n",
      "  File \"pandas/_libs/parsers.pyx\", line 374, in pandas._libs.parsers.TextReader.__cinit__\n",
      "  File \"pandas/_libs/parsers.pyx\", line 674, in pandas._libs.parsers.TextReader._setup_parser_source\n",
      "FileNotFoundError: [Errno 2] File ../output_data/cities.csv does not exist: '../output_data/cities.csv'\n",
      "\n",
      "During handling of the above exception, another exception occurred:\n",
      "\n",
      "Traceback (most recent call last):\n",
      "  File \"/Users/nicolebroussard/opt/anaconda3/envs/PythonData/lib/python3.6/site-packages/IPython/core/interactiveshell.py\", line 2044, in showtraceback\n",
      "    stb = value._render_traceback_()\n",
      "AttributeError: 'FileNotFoundError' object has no attribute '_render_traceback_'\n",
      "\n",
      "During handling of the above exception, another exception occurred:\n",
      "\n",
      "Traceback (most recent call last):\n",
      "  File \"/Users/nicolebroussard/opt/anaconda3/envs/PythonData/lib/python3.6/site-packages/IPython/core/interactiveshell.py\", line 3263, in run_ast_nodes\n",
      "    if (await self.run_code(code, result,  async_=asy)):\n",
      "  File \"/Users/nicolebroussard/opt/anaconda3/envs/PythonData/lib/python3.6/site-packages/IPython/core/interactiveshell.py\", line 3360, in run_code\n",
      "    self.showtraceback(running_compiled_code=True)\n",
      "  File \"/Users/nicolebroussard/opt/anaconda3/envs/PythonData/lib/python3.6/site-packages/IPython/core/interactiveshell.py\", line 2047, in showtraceback\n",
      "    value, tb, tb_offset=tb_offset)\n",
      "  File \"/Users/nicolebroussard/opt/anaconda3/envs/PythonData/lib/python3.6/site-packages/IPython/core/ultratb.py\", line 1436, in structured_traceback\n",
      "    self, etype, value, tb, tb_offset, number_of_lines_of_context)\n",
      "  File \"/Users/nicolebroussard/opt/anaconda3/envs/PythonData/lib/python3.6/site-packages/IPython/core/ultratb.py\", line 1336, in structured_traceback\n",
      "    self, etype, value, tb, tb_offset, number_of_lines_of_context\n",
      "  File \"/Users/nicolebroussard/opt/anaconda3/envs/PythonData/lib/python3.6/site-packages/IPython/core/ultratb.py\", line 1193, in structured_traceback\n",
      "    tb_offset)\n",
      "  File \"/Users/nicolebroussard/opt/anaconda3/envs/PythonData/lib/python3.6/site-packages/IPython/core/ultratb.py\", line 1150, in format_exception_as_a_whole\n",
      "    last_unique, recursion_repeat = find_recursion(orig_etype, evalue, records)\n",
      "  File \"/Users/nicolebroussard/opt/anaconda3/envs/PythonData/lib/python3.6/site-packages/IPython/core/ultratb.py\", line 451, in find_recursion\n",
      "    return len(records), 0\n",
      "TypeError: object of type 'NoneType' has no len()\n",
      "\n",
      "During handling of the above exception, another exception occurred:\n",
      "\n",
      "Traceback (most recent call last):\n",
      "  File \"/Users/nicolebroussard/opt/anaconda3/envs/PythonData/lib/python3.6/site-packages/IPython/core/interactiveshell.py\", line 2044, in showtraceback\n",
      "    stb = value._render_traceback_()\n",
      "AttributeError: 'TypeError' object has no attribute '_render_traceback_'\n",
      "\n",
      "During handling of the above exception, another exception occurred:\n",
      "\n",
      "Traceback (most recent call last):\n",
      "  File \"/Users/nicolebroussard/opt/anaconda3/envs/PythonData/lib/python3.6/site-packages/IPython/core/ultratb.py\", line 1169, in get_records\n",
      "    return _fixed_getinnerframes(etb, number_of_lines_of_context, tb_offset)\n",
      "  File \"/Users/nicolebroussard/opt/anaconda3/envs/PythonData/lib/python3.6/site-packages/IPython/core/ultratb.py\", line 316, in wrapped\n",
      "    return f(*args, **kwargs)\n",
      "  File \"/Users/nicolebroussard/opt/anaconda3/envs/PythonData/lib/python3.6/site-packages/IPython/core/ultratb.py\", line 350, in _fixed_getinnerframes\n",
      "    records = fix_frame_records_filenames(inspect.getinnerframes(etb, context))\n",
      "  File \"/Users/nicolebroussard/opt/anaconda3/envs/PythonData/lib/python3.6/inspect.py\", line 1490, in getinnerframes\n",
      "    frameinfo = (tb.tb_frame,) + getframeinfo(tb, context)\n",
      "  File \"/Users/nicolebroussard/opt/anaconda3/envs/PythonData/lib/python3.6/inspect.py\", line 1448, in getframeinfo\n",
      "    filename = getsourcefile(frame) or getfile(frame)\n",
      "  File \"/Users/nicolebroussard/opt/anaconda3/envs/PythonData/lib/python3.6/inspect.py\", line 696, in getsourcefile\n",
      "    if getattr(getmodule(object, filename), '__loader__', None) is not None:\n",
      "  File \"/Users/nicolebroussard/opt/anaconda3/envs/PythonData/lib/python3.6/inspect.py\", line 725, in getmodule\n",
      "    file = getabsfile(object, _filename)\n",
      "  File \"/Users/nicolebroussard/opt/anaconda3/envs/PythonData/lib/python3.6/inspect.py\", line 709, in getabsfile\n",
      "    return os.path.normcase(os.path.abspath(_filename))\n",
      "  File \"/Users/nicolebroussard/opt/anaconda3/envs/PythonData/lib/python3.6/posixpath.py\", line 383, in abspath\n",
      "    cwd = os.getcwd()\n",
      "PermissionError: [Errno 1] Operation not permitted\n"
     ]
    },
    {
     "name": "stderr",
     "output_type": "stream",
     "text": [
      "ERROR:root:Internal Python error in the inspect module.\n",
      "Below is the traceback from this internal error.\n",
      "\n"
     ]
    },
    {
     "name": "stdout",
     "output_type": "stream",
     "text": [
      "Traceback (most recent call last):\n",
      "  File \"/Users/nicolebroussard/opt/anaconda3/envs/PythonData/lib/python3.6/site-packages/IPython/core/interactiveshell.py\", line 3343, in run_code\n",
      "    exec(code_obj, self.user_global_ns, self.user_ns)\n",
      "  File \"<ipython-input-7-f59d68021fd8>\", line 5, in <module>\n",
      "    city_data_df = pd.read_csv(csv_path)\n",
      "  File \"/Users/nicolebroussard/opt/anaconda3/envs/PythonData/lib/python3.6/site-packages/pandas/io/parsers.py\", line 676, in parser_f\n",
      "    return _read(filepath_or_buffer, kwds)\n",
      "  File \"/Users/nicolebroussard/opt/anaconda3/envs/PythonData/lib/python3.6/site-packages/pandas/io/parsers.py\", line 448, in _read\n",
      "    parser = TextFileReader(fp_or_buf, **kwds)\n",
      "  File \"/Users/nicolebroussard/opt/anaconda3/envs/PythonData/lib/python3.6/site-packages/pandas/io/parsers.py\", line 880, in __init__\n",
      "    self._make_engine(self.engine)\n",
      "  File \"/Users/nicolebroussard/opt/anaconda3/envs/PythonData/lib/python3.6/site-packages/pandas/io/parsers.py\", line 1114, in _make_engine\n",
      "    self._engine = CParserWrapper(self.f, **self.options)\n",
      "  File \"/Users/nicolebroussard/opt/anaconda3/envs/PythonData/lib/python3.6/site-packages/pandas/io/parsers.py\", line 1891, in __init__\n",
      "    self._reader = parsers.TextReader(src, **kwds)\n",
      "  File \"pandas/_libs/parsers.pyx\", line 374, in pandas._libs.parsers.TextReader.__cinit__\n",
      "  File \"pandas/_libs/parsers.pyx\", line 674, in pandas._libs.parsers.TextReader._setup_parser_source\n",
      "FileNotFoundError: [Errno 2] File ../output_data/cities.csv does not exist: '../output_data/cities.csv'\n",
      "\n",
      "During handling of the above exception, another exception occurred:\n",
      "\n",
      "Traceback (most recent call last):\n",
      "  File \"/Users/nicolebroussard/opt/anaconda3/envs/PythonData/lib/python3.6/site-packages/IPython/core/interactiveshell.py\", line 2044, in showtraceback\n",
      "    stb = value._render_traceback_()\n",
      "AttributeError: 'FileNotFoundError' object has no attribute '_render_traceback_'\n",
      "\n",
      "During handling of the above exception, another exception occurred:\n",
      "\n",
      "Traceback (most recent call last):\n",
      "  File \"/Users/nicolebroussard/opt/anaconda3/envs/PythonData/lib/python3.6/site-packages/IPython/core/interactiveshell.py\", line 3263, in run_ast_nodes\n",
      "    if (await self.run_code(code, result,  async_=asy)):\n",
      "  File \"/Users/nicolebroussard/opt/anaconda3/envs/PythonData/lib/python3.6/site-packages/IPython/core/interactiveshell.py\", line 3360, in run_code\n",
      "    self.showtraceback(running_compiled_code=True)\n",
      "  File \"/Users/nicolebroussard/opt/anaconda3/envs/PythonData/lib/python3.6/site-packages/IPython/core/interactiveshell.py\", line 2047, in showtraceback\n",
      "    value, tb, tb_offset=tb_offset)\n",
      "  File \"/Users/nicolebroussard/opt/anaconda3/envs/PythonData/lib/python3.6/site-packages/IPython/core/ultratb.py\", line 1436, in structured_traceback\n",
      "    self, etype, value, tb, tb_offset, number_of_lines_of_context)\n",
      "  File \"/Users/nicolebroussard/opt/anaconda3/envs/PythonData/lib/python3.6/site-packages/IPython/core/ultratb.py\", line 1336, in structured_traceback\n",
      "    self, etype, value, tb, tb_offset, number_of_lines_of_context\n",
      "  File \"/Users/nicolebroussard/opt/anaconda3/envs/PythonData/lib/python3.6/site-packages/IPython/core/ultratb.py\", line 1193, in structured_traceback\n",
      "    tb_offset)\n",
      "  File \"/Users/nicolebroussard/opt/anaconda3/envs/PythonData/lib/python3.6/site-packages/IPython/core/ultratb.py\", line 1150, in format_exception_as_a_whole\n",
      "    last_unique, recursion_repeat = find_recursion(orig_etype, evalue, records)\n",
      "  File \"/Users/nicolebroussard/opt/anaconda3/envs/PythonData/lib/python3.6/site-packages/IPython/core/ultratb.py\", line 451, in find_recursion\n",
      "    return len(records), 0\n",
      "TypeError: object of type 'NoneType' has no len()\n",
      "\n",
      "During handling of the above exception, another exception occurred:\n",
      "\n",
      "Traceback (most recent call last):\n",
      "  File \"/Users/nicolebroussard/opt/anaconda3/envs/PythonData/lib/python3.6/site-packages/IPython/core/interactiveshell.py\", line 2044, in showtraceback\n",
      "    stb = value._render_traceback_()\n",
      "AttributeError: 'TypeError' object has no attribute '_render_traceback_'\n",
      "\n",
      "During handling of the above exception, another exception occurred:\n",
      "\n",
      "Traceback (most recent call last):\n",
      "  File \"/Users/nicolebroussard/opt/anaconda3/envs/PythonData/lib/python3.6/site-packages/IPython/core/interactiveshell.py\", line 2895, in _run_cell\n",
      "    return runner(coro)\n",
      "  File \"/Users/nicolebroussard/opt/anaconda3/envs/PythonData/lib/python3.6/site-packages/IPython/core/async_helpers.py\", line 68, in _pseudo_sync_runner\n",
      "    coro.send(None)\n",
      "  File \"/Users/nicolebroussard/opt/anaconda3/envs/PythonData/lib/python3.6/site-packages/IPython/core/interactiveshell.py\", line 3072, in run_cell_async\n",
      "    interactivity=interactivity, compiler=compiler, result=result)\n",
      "  File \"/Users/nicolebroussard/opt/anaconda3/envs/PythonData/lib/python3.6/site-packages/IPython/core/interactiveshell.py\", line 3282, in run_ast_nodes\n",
      "    self.showtraceback()\n",
      "  File \"/Users/nicolebroussard/opt/anaconda3/envs/PythonData/lib/python3.6/site-packages/IPython/core/interactiveshell.py\", line 2047, in showtraceback\n",
      "    value, tb, tb_offset=tb_offset)\n",
      "  File \"/Users/nicolebroussard/opt/anaconda3/envs/PythonData/lib/python3.6/site-packages/IPython/core/ultratb.py\", line 1436, in structured_traceback\n",
      "    self, etype, value, tb, tb_offset, number_of_lines_of_context)\n",
      "  File \"/Users/nicolebroussard/opt/anaconda3/envs/PythonData/lib/python3.6/site-packages/IPython/core/ultratb.py\", line 1336, in structured_traceback\n",
      "    self, etype, value, tb, tb_offset, number_of_lines_of_context\n",
      "  File \"/Users/nicolebroussard/opt/anaconda3/envs/PythonData/lib/python3.6/site-packages/IPython/core/ultratb.py\", line 1211, in structured_traceback\n",
      "    chained_exceptions_tb_offset)\n",
      "  File \"/Users/nicolebroussard/opt/anaconda3/envs/PythonData/lib/python3.6/site-packages/IPython/core/ultratb.py\", line 1150, in format_exception_as_a_whole\n",
      "    last_unique, recursion_repeat = find_recursion(orig_etype, evalue, records)\n",
      "  File \"/Users/nicolebroussard/opt/anaconda3/envs/PythonData/lib/python3.6/site-packages/IPython/core/ultratb.py\", line 451, in find_recursion\n",
      "    return len(records), 0\n",
      "TypeError: object of type 'NoneType' has no len()\n",
      "\n",
      "During handling of the above exception, another exception occurred:\n",
      "\n",
      "Traceback (most recent call last):\n",
      "  File \"/Users/nicolebroussard/opt/anaconda3/envs/PythonData/lib/python3.6/site-packages/IPython/core/interactiveshell.py\", line 2044, in showtraceback\n",
      "    stb = value._render_traceback_()\n",
      "AttributeError: 'TypeError' object has no attribute '_render_traceback_'\n",
      "\n",
      "During handling of the above exception, another exception occurred:\n",
      "\n",
      "Traceback (most recent call last):\n",
      "  File \"/Users/nicolebroussard/opt/anaconda3/envs/PythonData/lib/python3.6/site-packages/IPython/core/ultratb.py\", line 1169, in get_records\n",
      "    return _fixed_getinnerframes(etb, number_of_lines_of_context, tb_offset)\n",
      "  File \"/Users/nicolebroussard/opt/anaconda3/envs/PythonData/lib/python3.6/site-packages/IPython/core/ultratb.py\", line 316, in wrapped\n",
      "    return f(*args, **kwargs)\n",
      "  File \"/Users/nicolebroussard/opt/anaconda3/envs/PythonData/lib/python3.6/site-packages/IPython/core/ultratb.py\", line 350, in _fixed_getinnerframes\n",
      "    records = fix_frame_records_filenames(inspect.getinnerframes(etb, context))\n",
      "  File \"/Users/nicolebroussard/opt/anaconda3/envs/PythonData/lib/python3.6/inspect.py\", line 1490, in getinnerframes\n",
      "    frameinfo = (tb.tb_frame,) + getframeinfo(tb, context)\n",
      "  File \"/Users/nicolebroussard/opt/anaconda3/envs/PythonData/lib/python3.6/inspect.py\", line 1448, in getframeinfo\n",
      "    filename = getsourcefile(frame) or getfile(frame)\n",
      "  File \"/Users/nicolebroussard/opt/anaconda3/envs/PythonData/lib/python3.6/inspect.py\", line 696, in getsourcefile\n",
      "    if getattr(getmodule(object, filename), '__loader__', None) is not None:\n",
      "  File \"/Users/nicolebroussard/opt/anaconda3/envs/PythonData/lib/python3.6/inspect.py\", line 725, in getmodule\n",
      "    file = getabsfile(object, _filename)\n",
      "  File \"/Users/nicolebroussard/opt/anaconda3/envs/PythonData/lib/python3.6/inspect.py\", line 709, in getabsfile\n",
      "    return os.path.normcase(os.path.abspath(_filename))\n",
      "  File \"/Users/nicolebroussard/opt/anaconda3/envs/PythonData/lib/python3.6/posixpath.py\", line 383, in abspath\n",
      "    cwd = os.getcwd()\n",
      "PermissionError: [Errno 1] Operation not permitted\n"
     ]
    }
   ],
   "source": [
    "# File to Load (Remember to Change These)\n",
    "csv_path = \"../output_data/cities.csv\"\n",
    "\n",
    "# Read Purchasing File and store into Pandas data frame\n",
    "city_data_df = pd.read_csv(csv_path)\n",
    "city_data_df.head()\n"
   ]
  },
  {
   "cell_type": "markdown",
   "metadata": {},
   "source": [
    "### Humidity Heatmap\n",
    "* Configure gmaps.\n",
    "* Use the Lat and Lng as locations and Humidity as the weight.\n",
    "* Add Heatmap layer to map."
   ]
  },
  {
   "cell_type": "code",
   "execution_count": null,
   "metadata": {},
   "outputs": [],
   "source": [
    "# Access maps with unique API key\n",
    "gmaps.configure(api_key=gkey)"
   ]
  },
  {
   "cell_type": "code",
   "execution_count": null,
   "metadata": {},
   "outputs": [],
   "source": []
  },
  {
   "cell_type": "markdown",
   "metadata": {},
   "source": [
    "### Create new DataFrame fitting weather criteria\n",
    "* Narrow down the cities to fit weather conditions.\n",
    "* Drop any rows will null values."
   ]
  },
  {
   "cell_type": "code",
   "execution_count": null,
   "metadata": {},
   "outputs": [],
   "source": []
  },
  {
   "cell_type": "markdown",
   "metadata": {},
   "source": [
    "### Hotel Map\n",
    "* Store into variable named `hotel_df`.\n",
    "* Add a \"Hotel Name\" column to the DataFrame.\n",
    "* Set parameters to search for hotels with 5000 meters.\n",
    "* Hit the Google Places API for each city's coordinates.\n",
    "* Store the first Hotel result into the DataFrame.\n",
    "* Plot markers on top of the heatmap."
   ]
  },
  {
   "cell_type": "code",
   "execution_count": null,
   "metadata": {},
   "outputs": [],
   "source": []
  },
  {
   "cell_type": "code",
   "execution_count": null,
   "metadata": {},
   "outputs": [],
   "source": []
  },
  {
   "cell_type": "code",
   "execution_count": null,
   "metadata": {},
   "outputs": [],
   "source": [
    "# NOTE: Do not change any of the code in this cell\n",
    "\n",
    "# Using the template add the hotel marks to the heatmap\n",
    "info_box_template = \"\"\"\n",
    "<dl>\n",
    "<dt>Name</dt><dd>{Hotel Name}</dd>\n",
    "<dt>City</dt><dd>{City}</dd>\n",
    "<dt>Country</dt><dd>{Country}</dd>\n",
    "</dl>\n",
    "\"\"\"\n",
    "# Store the DataFrame Row\n",
    "# NOTE: be sure to update with your DataFrame name\n",
    "hotel_info = [info_box_template.format(**row) for index, row in hotel_df.iterrows()]\n",
    "locations = hotel_df[[\"Lat\", \"Lng\"]]"
   ]
  },
  {
   "cell_type": "code",
   "execution_count": null,
   "metadata": {},
   "outputs": [],
   "source": [
    "# Add marker layer ontop of heat map\n",
    "\n",
    "\n",
    "# Display figure\n"
   ]
  },
  {
   "cell_type": "code",
   "execution_count": null,
   "metadata": {},
   "outputs": [],
   "source": []
  }
 ],
 "metadata": {
  "kernelspec": {
   "display_name": "Python [conda env:PythonData] *",
   "language": "python",
   "name": "conda-env-PythonData-py"
  },
  "language_info": {
   "codemirror_mode": {
    "name": "ipython",
    "version": 3
   },
   "file_extension": ".py",
   "mimetype": "text/x-python",
   "name": "python",
   "nbconvert_exporter": "python",
   "pygments_lexer": "ipython3",
   "version": "3.6.10"
  },
  "latex_envs": {
   "LaTeX_envs_menu_present": true,
   "autoclose": false,
   "autocomplete": true,
   "bibliofile": "biblio.bib",
   "cite_by": "apalike",
   "current_citInitial": 1,
   "eqLabelWithNumbers": true,
   "eqNumInitial": 1,
   "hotkeys": {
    "equation": "Ctrl-E",
    "itemize": "Ctrl-I"
   },
   "labels_anchors": false,
   "latex_user_defs": false,
   "report_style_numbering": false,
   "user_envs_cfg": false
  }
 },
 "nbformat": 4,
 "nbformat_minor": 4
}
